Workbook

Sheet Totales
B11: TOTALES
B12: Editorial | D12: Subtotal | E12: Dto | F12: Total
B13: Ivrea | D13: =Ivrea!E3145 -> 0 | E13: 0.35 | F13: =D13*(100%-E13) -> 0
B14: Ovni Press | D14: =Ovnipress!F779 -> 0 | E14: 0.3 | F14: =D14*(100%-E14) -> 0
B15: Panini y utopia | D15: ='Panini-Utopia'!F1933 -> 0 | E15: 0.2 | F15: =D15*(100%-E15) -> 0
B16: Penguin | D16: =Penguin!F652 -> 0 | E16: 0.35 | F16: =D16*(100%-E16) -> 0
B17: Planeta | D17: =Planeta!E564 -> 0 | E17: 0.35 | F17: =D17*(100%-E17) -> 0
B18: Pop Fiction | D18: ='Deux-PopFiction'!G210 -> 0 | E18: 0.4 | F18: =D18*(100%-E18) -> 0
B19: Hotel de las Ideas | D19: ='Hotel de las Ideas'!F135 -> 0 | E19: 0.4 | F19: =D19*(100%-E19) -> 0
B20: V&R | D20: ='V&R'!F681 -> 0 | E20: 0.35 | F20: =D20*(100%-E20) -> 0
B21: Otras | D21: =Otras!F635 -> 0 | E21: 0.35 | F21: =D21*(100%-E21) -> 0
B22: Merchandising | D22: =Merchandising!E138 -> 0 | F22: =D22*(100%-E22) -> 0
B23: Total | F23: =SUM(F13:F22) -> 0
B26: TITULOS EN ROJO AGOTADOS TEMPORALMENTE, FAVOR DE NO PEDIR.

Sheet Ivrea
A8: POR FAVOR COMPLETAR LAS REEDICIONES ARRIBA. NO EN EL FONDO!
A9: NOVEDADES
A10: TITULO | B10: EAN | C10: PRECIO TAPA | D10: CANTIDAD | E10: Subtotal
A11: FRIEREN -MÁS ALLÁ DEL FINAL- PRELUDIO | B11: ISBN A CONFIRMAR | C11: 12500 | D11: 8 | E11: =Ivrea!$D11*C11 -> 0
A12: MOONLIGHT MILE -RERECORD EDITION- 01 | B12: ISBN A CONFIRMAR | C12: 27000 | D12: 1 | E12: =Ivrea!$D12*C12 -> 0
A13: SOLO LEVELING 14 - SIDE STORY 01 | B13: ISBN A CONFIRMAR | C13: 27900 | D13: 3 | E13: =Ivrea!$D13*C13 -> 0
A14: DANDADAN 22 | B14: ISBN A CONFIRMAR | C14: 9500 | D14: 13 | E14: =Ivrea!$D14*C14 -> 0
A15: CHAINSAW MAN 23 | B15: ISBN A CONFIRMAR | C15: 9500 | D15: 18 | E15: =Ivrea!$D15*C15 -> 0
A16: EL REY BESTIA Y LAS HIERBAS MEDICINALES 02 | B16: ISBN A CONFIRMAR | C16: 10500 | D16: 1 | E16: =Ivrea!$D16*C16 -> 0
A17: EVANGELION: ANIMA 04 | B17: ISBN A CONFIRMAR | C17: 17900 | D17: 2 | E17: =Ivrea!$D17*C17 -> 0
A18: YAKUZA LOVER 09 | B18: ISBN A CONFIRMAR | C18: 9500 | E18: =Ivrea!$D18*C18 -> 0
A19: YAKUZA LOVER 10 | B19: ISBN A CONFIRMAR | C19: 9500 | E19: =Ivrea!$D19*C19 -> 0
A20: YAKUZA LOVER 11 | B20: ISBN A CONFIRMAR | C20: 9500 | E20: =Ivrea!$D20*C20 -> 0
A21: YAKUZA LOVER 12 | B21: ISBN A CONFIRMAR | C21: 9500 | E21: =Ivrea!$D21*C21 -> 0
A22: AGENCIA DEL AMOR 02 | B22: ISBN A CONFIRMAR | C22: 10500 | D22: 7 | E22: =Ivrea!$D22*C22 -> 0
A23: GRAND BLUE 10 | B23: ISBN A CONFIRMAR | C23: 10500 | D23: 3 | E23: =Ivrea!$D23*C23 -> 0
A24: GRAND BLUE 11 | B24: ISBN A CONFIRMAR | C24: 10500 | D24: 3 | E24: =Ivrea!$D24*C24 -> 0
A25: BAKI THE GRAPPLER KANZENBAN 14 | B25: ISBN A CONFIRMAR | C25: 25500 | E25: =Ivrea!$D25*C25 -> 0
A26: BAKI THE GRAPPLER KANZENBAN 15 | B26: ISBN A CONFIRMAR | C26: 25500 | E26: =Ivrea!$D26*C26 -> 0
A27: D.N.ANGEL KANZENBAN 09 | B27: ISBN A CONFIRMAR | C27: 25500 | E27: =Ivrea!$D27*C27 -> 0
A28: D.N.ANGEL KANZENBAN 10 | B28: ISBN A CONFIRMAR | C28: 25500 | E28: =Ivrea!$D28*C28 -> 0
A29: GACHIAKUTA 14 | B29: ISBN A CONFIRMAR | C29: 9500 | D29: 8 | E29: =Ivrea!$D29*C29 -> 0
A30: REIMPRESIONES
A31: DEMON SLAYER - KIMETSU NO YAIBA: ARTBOOK | B31: 9788410475304 | C31: 33500 | D31: 5 | E31: =Ivrea!$D31*C31 -> 0
A32: SOLO LEVELING 02 | B32: 9788419383846 | C32: 27900 | D32: 1 | E32: =Ivrea!$D32*C32 -> 0
A33: MIS 100 NOVIAS QUE ME QUIEREN MUCHO MUCHO 01 | B33: 9791387500405 | C33: 10500 | D33: 2 | E33: =Ivrea!$D33*C33 -> 0
A34: MANGAS EN CURSO
A35: AGENCIA DEL AMOR 01 | B35: 9791388249303 | C35: 10500 | E35: =Ivrea!$D35*C35 -> 0
A36: ALICE ON BORDER ROAD 01 | B36: 9791387981891 | C36: 17900 | E36: =Ivrea!$D36*C36 -> 0
A37: ALICE ON BORDER ROAD 02 | B37: 9791388104114 | C37: 17900 | E37: =Ivrea!$D37*C37 -> 0
A38: ALICE ON BORDER ROAD 03 | B38: 9791388249389 | C38: 17900 | E38: =Ivrea!$D38*C38 -> 0
A39: AO ASHI 01 | B39: 9791388178504 | C39: 18900 | E39: =Ivrea!$D39*C39 -> 0
A40: ASADORA! 01 | B40: 9791387892609 | C40: 10500 | E40: =Ivrea!$D40*C40 -> 0
A41: ASADORA! 02 | B41: 9791387981853 | C41: 10500 | E41: =Ivrea!$D41*C41 -> 0
A42: ASADORA! 03 | B42: 9791388104824 | C42: 10500 | E42: =Ivrea!$D42*C42 -> 0
A43: ASADORA! 04 | B43: 9791388249471 | C43: 10500 | E43: =Ivrea!$D43*C43 -> 0
A44: ATELIER OF WITCH HAT 01 | B44: 9788418061899 | C44: 10500 | E44: =Ivrea!$D44*C44 -> 0
A45: ATELIER OF WITCH HAT 02 | B45: 9788418172755 | C45: 10500 | D45: 1 | E45: =Ivrea!$D45*C45 -> 0
A46: ATELIER OF WITCH HAT 03 | B46: 9788418271328 | C46: 10500 | D46: 1 | E46: =Ivrea!$D46*C46 -> 0
A47: ATELIER OF WITCH HAT 04 | B47: 9788418450846 | C47: 10500 | E47: =Ivrea!$D47*C47 -> 0
...

Sheet Ovnipress
A13: NOVEDADES
A14: Cant. de pág | B14: Título | C14: ISBN | D14: PVP | E14: CANT | F14: subtotal
A15: 128 | B15: DC - BLACK LABEL - DOOM PATROL: FLEX MENTALLO - EDICIÓN ABSOLUTA | C15: 978-987-819-535-3 | D15: 20000 | E15: 1 | F15: =E15*D15 -> 0
A16: 292 | B16: DC - BLACK LABEL - DOOM PATROL: LIBRO 1 (2da Edición) | C16: 978-987-819-533-9 | D16: 32000 | E16: 1 | F16: =E16*D16 -> 0
A17: 436 | B17: DC - FLASH vol. 3: CONFLICTO ELEMENTAL | C17: 978-987-819-617-6 | D17: 42000 | F17: =E17*D17 -> 0
A18: 352 | B18: MOZTROS - RENACIMIENTO DEL UNIVERSO VALIANT | C18: 978-84-10463-55-4 | D18: 28000 | E18: 1 | F18: =E18*D18 -> 0
C19: ISBN | D19: PVP | F19: subtotal
A20: 232 | B20: DC - BLACK LABEL - HELLBLAZER: ABRÁZAME (y otras historias) | C20: 978-987-819-615-2 | D20: 28000 | F20: =E20*D20 -> 0
A21: 208 | B21: DC - BLACK LABEL - SWAMP THING Vol. 01 (4ta Edición) | C21: 978-987-819-610-7 | D21: 28000 | F21: =E21*D21 -> 0
A22: 216 | B22: DC - LA NUEVA HISTORIA DEL UNIVERSO DC | C22: 978-987-819-618-3 | D22: 32000 | F22: =E22*D22 -> 0
A23: 144 | B23: MOZTROS - TEENAGE MUTANT NINJA TURTLES : ESPECIAL 40 ANIVERSARIO | C23: 978-84-10463-97-4 | D23: 26000 | F23: =E23*D23 -> 0
A24: 192 | B24: DC - ABSOLUTE BATMAN Vol. 1 (4ra Edicion) | C24: 978-987-819-565-0 | D24: 28000 | F24: =E24*D24 -> 0
A25: 208 | B25: DC - ABSOLUTE BATMAN Vol. 2 | C25: 978-987-819-560-5 | D25: 28000 | F25: =E25*D25 -> 0
A26: 168 | B26: DC - ABSOLUTE FLASH VOL 01 | C26: 978-987-819-509-4 | D26: 26000 | F26: =E26*D26 -> 0
A27: 176 | B27: DC - ABSOLUTE GREEN LANTERN Vol. 1 | C27: 978-987-819-614-5 | D27: 26000 | F27: =E27*D27 -> 0
A28: 160 | B28: DC - ABSOLUTE MARTIAN MANHUNTER Vol. 1 | C28: 978-987-819-519-3 | D28: 28000 | F28: =E28*D28 -> 0
A29: 168 | B29: DC - ABSOLUTE SUPERMAN Vol. 01 (2da edición) | C29: 978-987-819-525-4 | D29: 26000 | F29: =E29*D29 -> 0
A30: 208 | B30: DC - ABSOLUTE SUPERMAN Vol. 02 | C30: 978-987-819-602-2 | D30: 26000 | F30: =E30*D30 -> 0
A31: 184 | B31: DC - ABSOLUTE WONDER WOMAN VOL 01 | C31: 978-987-819-526-1 | D31: 26000 | F31: =E31*D31 -> 0
... A128: 296 | B128: DC - BATMAN: NO MAN'S LAND Vol. 3 - CATACLISMO (PARTE 1) | C128: 978-987-819-546-9 | D128: 30000 | F128: =E128*D128 -> 0
A129: 308 | B129: DC - BATMAN: NO MAN'S LAND Vol. 4 - CATACLISMO (PARTE 2) | C129: 978-987-819-593-3 | D129: 30000 | E129: 1 | F129: =E129*D129 -> 0
A130: 296 | B130: DC - BATMAN: PATRONES OSCUROS | C130: 978-987-819-601-5 | D130: 35000 | F130: =E130*D130 -> 0
A131: 136 | B131: DC - BATMAN: PRESA | C131: 978-987-819-241-3 | D131: 18000 | F131: =E131*D131 -> 0
A132: 200 | B132: DC - BATMAN: PRISIONES OSCURAS | C132: 978-987-819-387-8 | D132: 25000 | F132: =E132*D132 -> 0
A133: 312 | B133: DC - BATMAN: PRÓDIGO (EPÍLOGO A LA CAÍDA DEL CABALLERO) | C133: 978-987-819-295-6 | D133: 28000 | F133: =E133*D133 -> 0
A134: 136 | B134: DC - BATMAN: REFLEJOS | C134: 978-987-819-386-1 | D134: 20000 | F134: =E134*D134 -> 0
A135: 160 | B135: DC - BATMAN: RECUPERANDO LA CORDURA | C135: 978-987-819-544-5 | D135: 26000 | F135: =E135*D135 -> 0
A136: 136 | B136: DC - BATMAN: ROSTROS | C136: 978-987-819-284-0 | D136: 20000 | F136: =E136*D136 -> 0
A137: 188 | B137: DC - BATMAN: SANTUARIO | C137: 978-987-819-421-9 | D137: 22000 | F137: =E137*D137 -> 0
A138: 144 | B138: DC - BATMAN: SHAMAN | C138: 978-987-819-231-4 | D138: 22000 | F138: =E138*D138 -> 0
A139: 212 | B139: DC - BATMAN: TROIKA | C139: 978-987-819-346-5 | D139: 28000 | F139: =E139*D139 -> 0
A140: 288 | B140: DC - BATMAN: VAMPIRO | C140: 978-987-819-257-4 | D140: 30000 | F140: =E140*D140 -> 0
A141: 136 | B141: DC - BATMAN: VENENO | C141: 978-987-819-493-6 | D141: 20000 | F141: =E141*D141 -> 0
... A254: 218 | B254: DC - ECC - ESCUADRÓN SUICIDA Vol. 1 | C254: 978-84-17401-84-9 | D254: 22000 | F254: =E254*D254 -> 0
A255: 144 | B255: DC - ECC - FLASH Vol. 2 | C255: 978-84-17316-80-8 | F255: =E255*D255 -> 0
A256: 168 | B256: DC - ECC - HARLEY QUINN Vol. 1 | C256: 978-84-17106-65-2 | D256: 26000 | F256: =E256*D256 -> 0
A257: 168 | B257: DC - ECC - LIGA DE LA JUSTICIA Vol. 01 | C257: 978-84-17106-66-9 | D257: 23000 | F257: =E257*D257 -> 0
A258: 144 | B258: DC - ECC - LIGA DE LA JUSTICIA Vol. 02 | C258: 978-84-17316-85-3 | D258: 22000 | F258: =E258*D258 -> 0
A259: 120 | B259: DC - ECC - SUPERHIJOS Vol. 01 CUANDO SEA MAYOR… | C259: 978-84-17316-91-4 | D259: 22000 | F259: =E259*D259 -> 0
A260: 208 | B260: DC - ECC - SUPERMAN Vol. 02 | C260: 978-84-17316-74-7 | D260: 21000 | F260: =E260*D260 -> 0
...

Sheet Panini-Utopia
A8: NOVEDADES
A9: Código | B9: Titulo | C9: Isbn | D9: Precio en ARS | E9: Cant. | F9: Subtotal | G9: Columna1
B10: **PANINI MANGA **
B11: MARVEL FORTNITE CONFLICTO CERO 1 | F11: =E11*D11 -> 0
B12: MARVEL FORTNITE CONFLICTO CERO 5 | F12: =E12*D12 -> 0
A13: PCA40MADE01 | B13: 40 MADE NI SHITAI 10 NO KOTO 01 | C13: 9786075786834 | D13: 13000 | F13: =E13*D13 -> 0
A14: PCAAFTGOD01 | B14: AFTER GOD 01 | C14: 9786075820828 | D14: 12000 | F14: =E14*D14 -> 0
A15: PCAAFTGOD02 | B15: AFTER GOD 02 | C15: 9786075822570 | D15: 12000 | F15: =E15*D15 -> 0
A16: PCAAFTGOD03 | B16: AFTER GOD 03 | C16: 9786075823386 | D16: 12000 | F16: =E16*D16 -> 0
A17: PCAAFTGOD04 | B17: AFTER GOD 04 | C17: 9786075825724 | D17: 12000 | F17: =E17*D17 -> 0
A18: PCAAFTGOD05 | B18: AFTER GOD 05 | C18: 9786075828114 | D18: 12000 | F18: =E18*D18 -> 0
A19: PCAAFTGOD06 | B19: AFTER GOD 06 | C19: 9786075829685 | D19: 12000 | F19: =E19*D19 -> 0
A20: PCAAFTGOD07 | B20: AFTER GOD 07 | C20: 9786076382394 | D20: 12000 | F20: =E20*D20 -> 0
A21: PCAQAADE001 | B21: ALL OF US ARE DEAD 01 | C21: 9786076384664 | D21: 27000 | F21: =E21*D21 -> 0
A22: PCAAUNIKI01 | B22: ALL YOU NEED IS KILL 01 | C22: 9786075280264 | D22: 10500 | F22: =E22*D22 -> 0
A23: PCAAUNIKI02 | B23: ALL YOU NEED IS KILL 02 (ULTIMO TOMO) | C23: 9786075280769 | D23: 10500 | F23: =E23*D23 -> 0
A24: PCAASCLAS02 | B24: ASSASSINATION CLASSROOM 02 | C24: 9786075280554 | D24: 10500 | F24: =E24*D24 -> 0
... A118: PCABERSER41 | B118: BERSERK 41 | C118: 9786076360484 | D118: 13500 | F118: =E118*D118 -> 0
A119: PCABERSEV41 | B119: BERSERK 41 VARIANTE | C119: 7503041492610 | F119: =E119*D119 -> 0
A120: PCABERSER42 | B120: BERSERK 42 | C120: 9786075789613 | D120: 13500 | F120: =E120*D120 -> 0
A121: PCAQMBER042 | B121: BERSERK 42 TAROT EDITION | C121: 9786075823645 | F121: =E121*D121 -> 0
A122: PCABINTOU01 | B122: BLOOM INTO YOU 01 | C122: 9786075685267 | D122: 11000 | F122: =E122*D122 -> 0
A123: PCABINTOU02 | B123: BLOOM INTO YOU 02 | C123: 9786075685656 | D123: 11000 | F123: =E123*D123 -> 0
A124: PCABINTOU03 | B124: BLOOM INTO YOU 03 | C124: 9786075686189 | D124: 11000 | F124: =E124*D124 -> 0
A125: PCABINTOU04 | B125: BLOOM INTO YOU 04 | C125: 9786075686752 | D125: 11000 | F125: =E125*D125 -> 0
A126: PCABINTOU05 | B126: BLOOM INTO YOU 05 | C126: 9786075687285 | D126: 11000 | F126: =E126*D126 -> 0
A127: PCABINTOU06 | B127: BLOOM INTO YOU 06 | C127: 9786075687728 | D127: 11000 | F127: =E127*D127 -> 0
A128: PCABINTOU07 | B128: BLOOM INTO YOU 07 | C128: 9786075688633 | D128: 11000 | F128: =E128*D128 -> 0
A129: PCABINTOU08 | B129: BLOOM INTO YOU 08 (ULTIMO TOMO) | C129: 9786075689395 | D129: 11000 | F129: =E129*D129 -> 0
A130: PCABLUPER01 | B130: BLUE PERIOD 01 | C130: 9786076360446 | D130: 12000 | F130: =E130*D130 -> 0
A131: PCABLUPER02 | B131: BLUE PERIOD 02 | C131: 9786076361016 | D131: 12000 | F131: =E131*D131 -> 0
A132: PCABLUPER03 | B132: BLUE PERIOD 03 | C132: 9786076361566 | D132: 12000 | F132: =E132*D132 -> 0
A133: PCABLUPER04 | B133: BLUE PERIOD 04 | C133: 9786076362549 | D133: 12000 | F133: =E133*D133 -> 0
... A166: PCAIBOBL002 | B166: BORUTO TWO BLUE VORTEX 02 | C166: 9786075827032 | D166: 12000 | F166: =E166*D166 -> 0
A167: PCAWOTAKOPK | B167: BOX SET WOTAKOI TOMOS 01 AL 11 (COMPLETO) | C167: 7503036808525 | F167: =E167*D167 -> 0
A168: PCACLAYMO01 | B168: CLAYMORE 01 | C168: 9786076345764 | D168: 12000 | F168: =E168*D168 -> 0
A169: PCACLAYMO03 | B169: CLAYMORE 03 | C169: 9786076347027 | D169: 12000 | F169: =E169*D169 -> 0
A170: PCACLAYMO04 | B170: CLAYMORE 04 | C170: 9786076347218 | D170: 12000 | F170: =E170*D170 -> 0
A171: PCACLAYMO05 | B171: CLAYMORE 05 | C171: 9786076347225 | D171: 12000 | F171: =E171*D171 -> 0
A172: PCACLAYMO06 | B172: CLAYMORE 06 | C172: 9786076347812 | D172: 12000 | F172: =E172*D172 -> 0
...

Sheet Penguin
A11: NOVEDADES
A12: AUTOR | B12: NOMBRE | C12: ISBN | D12: PVP | E12: CANT. | F12: SUBTOTAL
A13: Wakui, Ken | B13: ASTRO ROYALE 2 | C13: 9786316657602 | D13: 14900 | F13: =E13*D13 -> 0
A14: Mashiro | B14: MI AMOR POR YAMADA ESTA AL NV. 999 6 | C14: 9786316657633 | D14: 14900 | F14: =E14*D14 -> 0
A15: Takamatsu, Misaki | B15: SKIP Y LOAFER 8 | C15: 9786316657640 | D15: 14900 | F15: =E15*D15 -> 0
A16: Bomhat | B16: REINO DE QUARTZ 4 | C16: 9786316657619 | D16: 14900 | F16: =E16*D16 -> 0
A17: Zec /Moscareto | B17: EL NUEVO EMPLEADO 1 | C17: 9786316657664 | D17: 22900 | E17: 1 | F17: =E17*D17 -> 0
A18: Score, Lucy | B18: EL ERROR DE MI VIDA (STORY LAKE 2) | C18: 9789877805895 | D18: 44499 | F18: =E18*D18 -> 0
A19: Jorge Pinarello | B19: ÉRASE UNA VEZ EN UN VIDEOCLUB | C19: 9789505612369 | D19: 35000 | F19: =E19*D19 -> 0
A20: Magaziner, Lauren | B20: RESUELVE EL MISTERIO. DIARIO DE ELIZA 2 | C20: 9789878121567 | D20: 39599 | F20: =E20*D20 -> 0
A21: RuNyx | B21: SOMBRA, LA (DARK VERSE 5) | C21: 9789877805932 | D21: 34999 | F21: =E21*D21 -> 0
A22: Bluey | B22: BLUEY. MINI BLUEY | C22: 9789877365825 | D22: 8599 | F22: =E22*D22 -> 0
A23: Ron, Mercedes | B23: CULPA VUESTRA | C23: 9786316620071 | D23: 41699 | F23: =E23*D23 -> 0
A24: Netflix | B24: KPOP DEMON HUNTERS: THE DELUXE JUNIOR NO | C24: 9786316620910 | D24: 23999 | F24: =E24*D24 -> 0
A25: Netflix | B25: KPOP DEMON HUNTERS: MY GOLDEN JOURNAL | C25: 9786316620927 | D25: 23999 | F25: =E25*D25 -> 0
A26: Clapés, Elizabeth | B26: ASI ES COMO LO VERAS MAÑANA | C26: 9786316620965 | D26: 30799 | F26: =E26*D26 -> 0
A27: Anónimo | B27: STICKERMANÍA - MUNDIAL | C27: 9786316718846 | D27: 8999 | F27: =E27*D27 -> 0
B28: ULTRAJUEGOS - CIRCO DEL HORROR | C28: 9786316718853 | D28: 10999 | F28: =E28*D28 -> 0
A29: Nik | B29: GATURRO 31 (TIRAS) | C29: 9789500772761 | D29: 15999 | F29: =E29*D29 -> 0
A30: Nik | B30: GATURRO 32 (TIRAS) | C30: 9789500772778 | D30: 15999 | F30: =E30*D30 -> 0
A31: Nik | B31: GATURRO 33 (TIRAS) | C31: 9789500772785 | D31: 15999 | F31: =E31*D31 -> 0
A32: Nik | B32: GATURRO 34 (TIRAS) | C32: 9789500772792 | D32: 15999 | F32: =E32*D32 -> 0
A33: Nik | B33: GATURRO 35 (TIRAS) | C33: 9789500772808 | D33: 15999 | F33: =E33*D33 -> 0
A34: Nik | B34: GATURRO 36 (TIRAS) | C34: 9789500772815 | D34: 15999 | F34: =E34*D34 -> 0
A35: Nik | B35: GATURRO 37 (TIRAS) | C35: 9789500772822 | D35: 15999 | F35: =E35*D35 -> 0
A36: Nik | B36: GATURRO 38 (TIRAS) | C36: 9789500772839 | D36: 15999 | F36: =E36*D36 -> 0
A37: Nik | B37: GATURRO 39 (TIRAS) | C37: 9789500772846 | D37: 15999 | F37: =E37*D37 -> 0
B38: PLANNER DEL PRINCIPITO | C38: 9789500773805 | D38: 19999 | F38: =E38*D38 -> 0
A39: El Bruno | B39: ESCUELA DE MONSTRUOS 7 | C39: 9789500773966 | D39: 16999 | F39: =E39*D39 -> 0
A40: Quino | B40: DEJENME INVENTAR | C40: 9789500773997 | D40: 19999 | F40: =E40*D40 -> 0
A41: Quino | B41: HUMANO SE NACE | C41: 9789500774000 | D41: 19999 | F41: =E41*D41 -> 0
A42: Vallejos, Lyna/Morro, Daniel | B42: LYNIEL 2 - EL JUEGO FINAL | C42: 9789877365832 | D42: 19999 | F42: =E42*D42 -> 0
A43: Saint-Exupéry, Antoine de/Hesse, María | B43: PRINCIPITO ILUSTRADO (MARIA HESSE) | C43: 9789878002743 | D43: 44999 | F43: =E43*D43 -> 0
B44: MANGA
A45: Kaneshiro, Muneyuki; Fujimura, Akeji | B45: AS THE GODS WILL 1 | C45: 9789878987057 | D45: 14900 | F45: =E45*D45 -> 0
A46: Kaneshiro, Muneyuki; Fujimura, Akeji | B46: AS THE GODS WILL 2 | C46: 9789878987194 | D46: 14900 | F46: =E46*D46 -> 0
A47: Kaneshiro, Muneyuki; Fujimura, Akeji | B47: AS THE GODS WILL 3 | C47: 9789878987255 | D47: 14900 | F47: =E47*D47 -> 0
A48: Kaneshiro, Muneyuki/Fujimura, Akeji | B48: AS THE GODS WILL 4 | C48: 9789878987361 | D48: 14900 | F48: =E48*D48 -> 0
A49: Kaneshiro, Muneyuki; Fujimura, Akeji | B49: AS THE GODS WILL 5 | C49: 9789878987422 | D49: 14900 | F49: =E49*D49 -> 0
A50: Kaneshiro, Muneyuki/Fujimura, Akeji | B50: AS THE GODS WILL (SECUELA) 1 | C50: 9789878987668 | D50: 22900 | F50: =E50*D50 -> 0
...

Sheet Planeta
A10: NOVEDADES DICIEMBRE
A11: TITULO | B11: EAN | C11: PVP | D11: Cantidad | E11: Subtotal
A12: STAR WARS ANTOLOGIA (ED. LIMIT ADA) | B12: 9788491460688 | C12: 79900 | E12: =D12*C12 -> 0 | F12: NOVEDAD
A13: STAR WARS NUEVA ENCICLOPEDIA D E PERSONAJES ACTUALIZADA | B13: 9788413429427 | C13: 42900 | E13: =D13*C13 -> 0 | F13: NOVEDAD
A14: STAR WARS VESTUARIO | B14: 9788416476596 | C14: 49900 | E14: =D14*C14 -> 0 | F14: NOVEDAD
A15: STAR WARS. THE MANDALORIAN (COMIC) | B15: 9788411121934 | C15: 24900 | E15: =D15*C15 -> 0 | F15: NOVEDAD
A16: PALESTINA | B16: 9788411618458 | C16: 26900 | E16: =D16*C16 -> 0 | F16: NOVEDAD
A17: COMO SE HIZO EPISODIO VI EL RE TORNO DEL JEDI | B17: 9788491461647 | C17: 59900 | E17: =D17*C17 -> 0 | F17: NOVEDAD
A18: COMO SE HIZO STAR WARS UNA NUE VA ESPERANZA | B18: 9788416090648 | C18: 59900 | E18: =D18*C18 -> 0 | F18: NOVEDAD
A19: STAR WARS LOS PLANOS (SW BLUEP RINTS) | B19: 9788416693900 | C19: 99900 | E19: =D19*C19 -> 0 | F19: NOVEDAD
A20: EL ARTE DE STAR WARS: THE MAND ALORIAN | B20: 9788413419176 | C20: 49900 | E20: =D20*C20 -> 0 | F20: NOVEDAD
A21: STAR WARS. AHSOKA | B21: 9791387779979 | C21: 32900 | E21: =D21*C21 -> 0 | F21: NOVEDAD
A22: STAR WARS. THE MANDALORIAN (COMIC) TEMPORADA 2 | B22: 9788411618779 | C22: 32900 | E22: =D22*C22 -> 0 | F22: NOVEDAD
A23: NAUSICAA Nº 04 | B23: 9789504996064 | C23: 32900 | E23: =D23*C23 -> 0
A24: MIENTRAS YUBOOH DUERME 6 | B24: 9789504996859 | C24: 29900 | E24: =D24*C24 -> 0
A25: COMENTARIOS AL NÁUCRATO. NOVELA GRÁFICA | B25: 9789504992974 | C25: 23900 | E25: =D25*C25 -> 0
A26: ¡ABRAZA A TU AMIGO FIEL! TOY STORY | B26: 9789504996293 | C26: 29900 | E26: =D26*C26 -> 0
A27: ALAS DE SANGRE. EDICIÓN ESPECIAL LIMITADA | B27: 9786073939300 | C27: 41900 | E27: =D27*C27 -> 0
A28: PURO FÚTBOL | B28: 9789878224008 | C28: 19900 | E28: =D28*C28 -> 0
A29: CÓMO ENTRENAR A TU DRAGÓN. ESCUELA DE DRAGONES | B29: 9789504996873 | C29: 29900 | E29: =D29*C29 -> 0
A30: QUIERO VERTE OTRA VEZ | B30: 9789878223995 | C30: 19900 | E30: =D30*C30 -> 0
A31: EL MANUAL DEL HINCHA | B31: 9789878224015 | C31: 19900 | E31: =D31*C31 -> 0
A32: EL MUNDO HA VIVIDO EQUIVOCADO | B32: 9789878224022 | C32: 19900 | E32: =D32*C32 -> 0
A33: REBELIÓN EN LA GRANJA | B33: 9789878224039 | C33: 22900 | E33: =D33*C33 -> 0
A34: TWISTED 3. TWISTED HATE | B34: 9789878224084 | C34: 35900 | E34: =D34*C34 -> 0
... A40: TRIFONÍA & BALDOMERO | B40: 9789504996866 | C40: 36900 | E40: =D40*C40 -> 0
A41: OFERTA PLANETA ESPAÑA
A42: EL REY FANTASMA | B42: 9788448037963 | C42: 25900 | E42: =D42*C42 -> 0
A43: EL REY ORCO | B43: 9788448037949 | C43: 25900 | E43: =D43*C43 -> 0
A44: USAGI YOJIMBO SAGA LIBRO 4 | B44: 9788491735700 | C44: 30500 | E44: =D44*C44 -> 0
A45: USAGI YOJIMBO SAGA LIBRO 1 | B45: 9788416816446 | C45: 30500 | E45: =D45*C45 -> 0
A46: VINLAND SAGA 23 | B46: 9788413416311 | C46: 9700 | E46: =D46*C46 -> 0
A47: TEZUCOMI 1 | B47: 9788413415895 | C47: 20900 | E47: =D47*C47 -> 0
A48: TEZUCOMI 2 | B48: 9788413416854 | C48: 20900 | E48: =D48*C48 -> 0
A49: HAY ALGO MATANDO A LOS NIÑOS 1 (TAPA DURA) | B49: 9788413416441 | C49: 10900 | E49: =D49*C49 -> 0
A50: EL LOBO SOLITARIO Y SU CACHORRO 02 | B50: 9788416693184 | C50: 22000 | E50: =D50*C50 -> 0
A51: EL LOBO SOLITARIO Y SU CACHORRO 03 | B51: 9788416693191 | C51: 22000 | E51: =D51*C51 -> 0
A52: EL LOBO SOLITARIO Y SU CACHORRO 04 | B52: 9788416636594 | C52: 22000 | E52: =D52*C52 -> 0
A53: EL LOBO SOLITARIO Y SU CACHORRO 05 | B53: 9788416636600 | C53: 22000 | E53: =D53*C53 -> 0
... A73: BABYTEETH 1: EL NACIMIENTO | B73: 9788491737353 | C73: 10900 | E73: =D73*C73 -> 0
...

Sheet Deux-PopFiction
A12: LANZAMIENTOS
A14: PRODUCTO | B14: SELLO | C14: TITULO | D14: ISBN | E14: pvp ACTUAL | F14: Cantidad | G14: Subtotal
A15: MANGA | B15: POP FICTION | C15: LOVE IN HELL 2 | D15: 9789878905150 | E15: 19500 | G15: =F15*E15 -> 0 | H15: NOVEDAD
A16: Historieta Argentina | B16: Deux | C16: BLOODTOWN | D16: 9789871485345 | E16: 23900 | G16: =F16*E16 -> 0
A17: Historieta Argentina | B17: Deux | C17: LOS SIGLOS OSCUROS VOL 3 | D17: 9786316536907 | E17: 25900 | G17: =F17*E17 -> 0
A18: Historieta Argentina | B18: Deux | C18: FALKA 2: EL CRISTAL ROJO | D18: 9789871485352 | E18: 24400 | G18: =F18*E18 -> 0
A19: Historieta Argentina | B19: Deux | C19: ¡NO MATARÁS! | D19: 9789872347093 | E19: 22900 | G19: =F19*E19 -> 0
A20: Historieta Argentina | B20: Deux | C20: EL COLOR DE LA MUERTE | D20: 9789871485468 | E20: 23900 | G20: =F20*E20 -> 0
A21: PRODUCTO | B21: SELLO | C21: DEUX ESTUDIO | E21: pvp ACTUAL | F21: Cantidad | G21: Subtotal
A22: Historieta Argentina | B22: Deux | C22: ¿POR QUÉ DESAPARECIERON LOS CABALLEROS? | D22: 9786316536815 | E22: 17900 | G22: =F22*E22 -> 0
A23: Cómic Americano | B23: Deux | C23: 30 DIAS DE NOCHE LA SAGA ORIGINAL | D23: 7798290036054 | E23: 10000 | G23: =F23*E23 -> 0
A24: Cómic Americano | B24: Pop Fiction | C24: ALIEN LA HISTORIA ILUSTRADA | D24: 9789874717153 | E24: 28500 | G24: =F24*E24 -> 0
A25: Comic nacional | B25: Deux | C25: ALFABETO EROTICO (EL TOMI / CLARA RODRIGUEZ) | D25: 9786319046939 | E25: 18900 | G25: =F25*E25 -> 0
A26: COMIC NACIONAL | B26: DEUX | C26: ALMANZOR | D26: 9786319046946 | E26: 19900 | G26: =F26*E26 -> 0
A27: Historieta Argentina | B27: Deux | C27: ARGENTINA POTENCIA | D27: 9789871485802 | E27: 24900 | G27: =F27*E27 -> 0
A28: Cómic Americano | B28: Deux | C28: BAD BOY (FRANK MILLER-SIMON BISLEY) | D28: 9789871485307 | E28: 21900 | G28: =F28*E28 -> 0
A29: Historieta Argentina | B29: Deux | C29: BIG RAG | D29: 9786316536372 | E29: 29500 | G29: =F29*E29 -> 0
A30: Historieta Argentina | B30: Deux | C30: BROWNING & COPPER | D30: 9786316536570 | E30: 24900 | G30: =F30*E30 -> 0
A31: Historieta Argentina | B31: Deux | C31: CABALLEROS COLECCIÓN ESENCIAL TOMO 1 | D31: 9789871485093 | E31: 24900 | G31: =F31*E31 -> 0
A32: COMIC NACIONAL | B32: DEUX | C32: CABALLEROS COLECCIÓN ESENCIAL TOMO 3 | D32: 9786316536433 | E32: 24900 | G32: =F32*E32 -> 0
A33: Historieta Argentina | B33: Deux | C33: CABALLEROS COLECCIÓN ESENCIAL TOMO 4 | D33: 9786316536594 | E33: 24900 | G33: =F33*E33 -> 0
... A53: Historieta Argentina | B53: Deux | C53: CRONICAS DE LOCKANN | D53: 9789871485901 | E53: 22900 | G53: =F53*E53 -> 0
A54: Historieta Argentina | B54: Deux | C54: CRONICAS DEL TIEMPO MEDIO INTEGRAL BYN | D54: 9789874881366 | E54: 29900 | G54: =F54*E54 -> 0
A55: Historieta Argentina | B55: Deux | C55: CRONICAS DEL TIEMPO MEDIO INTEGRAL COLOR | D55: 9789871485857 | E55: 35900 | G55: =F55*E55 -> 0
A56: Historieta Argentina | B56: Deux | C56: CRONICAS DEL TIEMPO MEDIO: LA PRECUELA VOL 1 | D56: 9789871485994 | E56: 23500 | G56: =F56*E56 -> 0
A57: Historieta Argentina | B57: Deux | C57: CRONICAS DEL TIEMPO MEDIO: LA PRECUELA VOL 2 | D57: 9786316536099 | E57: 23500 | G57: =F57*E57 -> 0
A58: Historieta Argentina | B58: Deux | C58: CRONICAS DEL TIEMPO MEDIO: LA PRECUELA VOL 3 (FINAL) | D58: ISBN A CONFIRMAR | E58: 23500 | G58: =F58*E58 -> 0
A59: Historieta Argentina | B59: Deux | C59: CUENTOS PARA NADA INFANTILES | D59: 9786316536143 | E59: 22900 | G59: =F59*E59 -> 0
A60: Historieta Argentina | B60: Deux | C60: DEREK OBRA COMPLETA | D60: ISBN A CONFIRMAR | E60: 29900 | G60: =F60*E60 -> 0
A61: Historieta Argentina | B61: Deux | C61: DON NICOLA | D61: 9786316536266 | E61: 29900 | G61: =F61*E61 -> 0
A62: Historieta Argentina | B62: Deux | C62: EKATON EL PUEBLO PERDIDO DEL ESPACIO 2da Ed. | D62: 9786316536105 | E62: 23900 | G62: =F62*E62 -> 0
A63: Historieta Argentina | B63: Deux | C63: EL BUITRE ES UN AVE DE PASO | D63: ISBN A CONFIRMAR | E63: 27500 | G63: =F63*E63 -> 0
A64: Historieta Argentina | B64: Deux | C64: EL COBRA VOLUMEN 1 (REEDICIÓN) | D64: 9789874881380 | E64: 21900 | G64: =F64*E64 -> 0
A65: Historieta Argentina | B65: Deux | C65: EL COBRA VOLUMEN 2 | D65: 9786316536242 | E65: 21900 | G65: =F65*E65 -> 0
A66: COMIC NACIONAL | B66: DEUX | C66: EL COBRA VOLUMEN 3 | D66: 9786316536440 | E66: 23900 | G66: =F66*E66 -> 0
A67: COMIC NACIONAL | B67: DEUX | C67: EL COBRA 4 | D67: 9786316536532 | E67: 23900 | G67: =F67*E67 -> 0
A68: Comic nacional | B68: Deux | C68: EL CONVENTILLO DE DON NICOLA | D68: 9786316536266 | E68: 29900 | G68: =F68*E68 -> 0
A69: Historieta Argentina | B69: Deux | C69: EL CONVENTILLO DE DON NICOLA 2 | D69: 9786316536587 | E69: 29900 | G69: =F69*E69 -> 0
A70: COMIC EUROPEO | B70: DEUX | C70: EL CORAZÓN CORONADO | D70: 9789871485321 | E70: 29500 | G70: =F70*E70 -> 0
A71: Historieta Argentina | B71: Deux | C71: EL ESPIRITU DE MASCARIN (TOMO UNICO) | D71: 9786316536211 | E71: 29900 | G71: =F71*E71 -> 0
...

Sheet Hotel de las Ideas
A10: Autor | B10: Título | C10: ISBN | D10: PVP | E10: Cantidad | F10: Subtotal
A11: varios | B11: EN LA ESQUINA DE MI BARRIO | C11: 9786319145649 | D11: 18000 | F11: =E11*D11 -> 0 | G11: NOVEDAD
A12: KAGO, SHINTARO | B12: DEMENCIA 21 | C12: 9789874164933 | D12: 26000 | F12: =E12*D12 -> 0
A13: KAGO, SHINTARO | B13: DEMENCIA 21 Vol. 2 | C13: 9786319145601 | D13: 26000 | F13: =E13*D13 -> 0
A14: SALA,GUSTAVO | B14: ¡VIVA LA CACA! | C14: 9789874164032 | D14: 17000 | F14: =E14*D14 -> 0
A15: BRECCIA, ALBERTO | B15: ¿DRÁCULA, DRACÚL, VLAD?¡BAH…! | C15: 9789874164216 | D15: 19000 | F15: =E15*D15 -> 0
A16: AGRIMBAU, DIEGO | B16: ¿QUIÉN MATÓ A REXTON? | C16: 9789874164162 | D16: 20000 | F16: =E16*D16 -> 0
A17: CALVI, FERNANDO | B17: AL REY DE CONSTANTINOPLA | C17: 9789874164247 | D17: 17000 | F17: =E17*D17 -> 0
A18: MANCINI, PEDRO | B18: ALIEN TRISTE | C18: 9789874592200 | D18: 20000 | F18: =E18*D18 -> 0
A19: MANCINI, PEDRO | B19: ALIEN TRISTE. DÍAS ESPECTRALES | C19: 9789874164605 | D19: 20000 | F19: =E19*D19 -> 0
A20: FEMIMUTANCIA | B20: ALIENIGENA | C20: 9789874164230 | D20: 20000 | F20: =E20*D20 -> 0
A21: CALVI, FERNANDO | B21: ALTAVISTA | C21: 9789873344879 | D21: 22000 | F21: =E21*D21 -> 0
A22: LUNIK, ALEJANDRA | B22: ANDÁ A LAVAR LOS PLATOS | C22: 9789874164346 | D22: 19000 | F22: =E22*D22 -> 0
A23: TEJADA-DEARMAS | B23: APAGÓN | C23: 9789874164629 | D23: 20000 | F23: =E23*D23 -> 0
... A121: CALVI, FERNANDO | B121: ZONIA | C121: 9789874164490 | D121: 17000 | F121: =E121*D121 -> 0
B123: AGUA NEGRA
A124: AGRIMBAU-PIETRO | B124: CIELOALTO | C124: 9789872774769 | D124: 19000 | F124: =E124*D124 -> 0
A125: BOBILLO, JUAN | B125: COCA, RAMÓN Y FERNET | C125: 9789872774745 | D125: 13000 | F125: =E125*D125 -> 0
A126: AA.VV. | B126: ENTRELINEAS | C126: 2408-3844 | D126: 13000 | F126: =E126*D126 -> 0
A127: VÁZQUEZ, LAURA | B127: FUERA DE CUADRO | C127: 9789872774776 | D127: 19000 | F127: =E127*D127 -> 0
A128: AA.VV. | B128: MAL TIEMPO | C128: 9789872774752 | D128: 13000 | F128: =E128*D128 -> 0
A129: SAENZ VALIENTE, JUAN | B129: MATUFIA | C129: 9789874501837 | D129: 13000 | F129: =E129*D129 -> 0
A130: TREIBEL-BOBILLO | B130: PLAN C | C130: 9789874501844 | D130: 19000 | F130: =E130*D130 -> 0
A131: AMAYA-HURÓN-ORTIZ | B131: ZOK! | C131: 9789874501820 | D131: 13000 | F131: =E131*D131 -> 0
B135: TOTAL HOTEL DE LAS IDEAS | F135: =SUM(F1:F134) -> 0

Sheet V&R
A1: NOVEDADES
A2: JULIE CAMEL (ILUSTRACIONES) | B2: MM - CREA TUS MUÑECAS MEXICANAS - GABRIELA | C2: 9789877478921 | D2: 25500 | F2: =E2*D2 -> 0
A3: JULIE CAMEL (ILUSTRACIONES) | B3: MM - CREA TUS MUÑECAS PORTUGUESAS - ROSA | C3: 9789877479997 | D3: 25500 | F3: =E3*D3 -> 0
A4: JULIE CAMEL (ILUSTRACIONES) | B4: MM - CREA TUS MUÑECAS TAILANDESAS - ANONG | C4: 9789877479973 | D4: 25500 | F4: =E4*D4 -> 0
A5: JULIE CAMEL (ILUSTRACIONES) | B5: MM - CREA TUS MUÑECAS ALEMANAS - CLARA | C5: 9789877479966 | D5: 25500 | F5: =E5*D5 -> 0
A6: JENNIFER NIVEN | B6: CUANDO FUIMOS MONSTRUOS | C6: 9786313006472 | D6: 42000 | F6: =E6*D6 -> 0
A7: ANIBAL LITVIN | B7: EL LIBRO DE ORO DE LA SCALONETA | C7: 9786313006595 | D7: 26000 | F7: =E7*D7 -> 0
A8: ELEANOR HAWKEN | B8: CRIATURAS MONSTRUOSAS | C8: 9786313004959 | D8: 51000 | F8: =E8*D8 -> 0
A9: MÉLANIE GRANDGIRARD | B9: BUSCA Y ENCUENTRA - MI ESCUELA | C9: 9786313004560 | D9: 32000 | F9: =E9*D9 -> 0
A10: SIMON MUGFORD | B10: ESTRELLAS DEL FÚTBOL: MBAPPÉ | C10: 9786313006113 | D10: 17000 | F10: =E10*D10 -> 0
A11: GALE - CHIAK | B11: FÚTBOL A TODO COLOR | C11: 9786313006496 | D11: 18000 | F11: =E11*D11 -> 0
A12: SHAKESPEARE, WILLIAN | B12: ROMEO Y JULIETA | C12: 9786313006816 | D12: 19800 | F12: =E12*D12 -> 0
A13: MACHIDA, SONOKO | B13: LA TIENDA JUNTO AL MAR | C13: 9786313006601 | D13: 38000 | F13: =E13*D13 -> 0
... A24: NOELIA PACE | B24: SESIÓN ABIERTA : LAS ALMAS CONECTAN, EL ESPÍRITU SANA - ED DE LUJO | C24: 9786313005444 | D24: 40000 | F24: =E24*D24 -> 0
A25: NOVEDADES ABRIL
A26: KATH JEWITT | B26: YO SOY...VALIENTE | C26: 9786313004003 | D26: 20000 | F26: =E26*D26 -> 0
A27: KATH JEWITT | B27: YO SOY... FELIZ | C27: 9786313003990 | D27: 20000 | F27: =E27*D27 -> 0
A28: KATH JEWITT | B28: YO SOY... PACIENTE | C28: 9786313003983 | D28: 20000 | F28: =E28*D28 -> 0
A29: KATH JEWITT | B29: YO SOY... AMABLE | C29: 9786313004027 | D29: 20000 | F29: =E29*D29 -> 0
A30: ANÓNIMO | B30: MANUAL DE SUPERVIVENCIA SKIBIDI TOILET - OFICIAL | C30: 9786313006267 | D30: 23000 | F30: =E30*D30 -> 0
A31: KIM BUSSING | B31: CAMBIO DE PRINCESAS - CENICIENTA Y LA BESTIA O BELLA Y EL ZAPATITO DE CRISTAL | C31: 9786313006465 | D31: 37000 | F31: =E31*D31 -> 0
A32: YOKO MURE | B32: UN DÍA PARA SOPAS, PAN Y GATOS | C32: 9786313006090 | D32: 36000 | F32: =E32*D32 -> 0
A33: BAL KHABRA | B33: REVOLVE | C33: 9786313006489 | D33: 40000 | F33: =E33*D33 -> 0
A34: AUSTIN BAECHLE | B34: LOS AVENGERS - EL LIBRO OFICIAL PARA COLOREAR FUNKO POP! | C34: 9786313005147 | D34: 23000 | F34: =E34*D34 -> 0
A35: ADRIANA ALLEGRI | B35: LA CASA DE LOS GIRASOLES | C35: 9786313006441 | D35: 41000 | F35: =E35*D35 -> 0
A36: SIMON MUGFORD | B36: ESTRELLAS DEL FÚTBOL: MESSI | C36: 9786313006106 | D36: 17000 | F36: =E36*D36 -> 0
A37: SIMON MUGFORD | B37: ESTRELLAS DEL FÚTBOL: RONALDO | C37: 9786313006120 | D37: 17000 | F37: =E37*D37 -> 0
... A39: BETA SUÁREZ | B39: ROTO | C39: 9786313006458 | D39: 37000 | F39: =E39*D39 -> 0
A40: NOVEDADES MARZO
A41: ANÓNIMO | B41: MENTES BRILLANTES: 8-9 AÑOS | C41: 9786313003563 | D41: 15000 | F41: =E41*D41 -> 0
A42: ANÓNIMO | B42: MENTES BRILLANTES: 7-8 AÑOS | C42: 9786313003556 | D42: 15000 | F42: =E42*D42 -> 0
A43: ANÓNIMO | B43: MENTES BRILLANTES: 6-7 AÑOS | C43: 9786313003549 | D43: 15000 | F43: =E43*D43 -> 0
A44: ANÓNIMO | B44: MENTES BRILLANTES: 5-6 AÑOS | C44: 9786313003532 | D44: 15000 | F44: =E44*D44 -> 0
A45: ANÓNIMO | B45: MENTES BRILLANTES: 4-5 AÑOS | C45: 9786313003525 | D45: 15000 | F45: =E45*D45 -> 0
A46: ANÓNIMO | B46: MENTES BRILLANTES: 3-4 AÑOS | C46: 9786313003518 | D46: 15000 | F46: =E46*D46 -> 0
A47: SIMON MUGFORD | B47: SUPERESTRELLAS DEL DEPORTE: VERSTAPPEN | C47: 9786313005758 | D47: 17000 | F47: =E47*D47 -> 0
A48: SIMON MUGFORD | B48: SUPERESTRELLAS DEL DEPORTE: HAMILTON | C48: 9786313005741 | D48: 17000 | F48: =E48*D48 -> 0
A49: ELEONORA MERIGHI | B49: LAS RUNAS CONTADAS | C49: 9786313006410 | D49: 30000 | F49: =E49*D49 -> 0
A50: JENNIFER HARTMANN | B50: MIENTRAS SIGA LATIENDO | C50: 9786313006342 | D50: 42900 | F50: =E50*D50 -> 0
A51: REBBECCA YARROS | B51: NOVA | C51: 9786313006359 | D51: 46200 | F51: =E51*D51 -> 0
...

Sheet Otras
A1: Autor | B1: Nombre | C1: ISBN | D1: Precio | E1: Cant. | F1: Subtotal
A2: MARVEL - LA HISTORIA VISUAL
A3: MARVEL LA HISTORIA VISUAL | B3: 1939 A 1949 EN LOS PRINCIPIOS | C3: 9780241388136 | D3: 5000 | F3: =E3*D3 -> 0
A4: MARVEL LA HISTORIA VISUAL | B4: 1950 A 1959 LOS VIENTOS DE CAMBIO | C4: 9780241388143 | D4: 5000 | F4: =E4*D4 -> 0
A5: MARVEL LA HISTORIA VISUAL | B5: 1960 A 1964 EL RENACER DEL SUPERHÉROE | C5: 9780241388150 | D5: 5000 | F5: =E5*D5 -> 0
A6: MARVEL LA HISTORIA VISUAL | B6: 1965 A 1969 MARVEL EN LA CULTURA COMERCIAL | C6: 9780241388198 | D6: 5000 | F6: =E6*D6 -> 0
A7: MARVEL LA HISTORIA VISUAL | B7: 1970 A 1979 HACIENDO HISTORIA | C7: 9780241388204 | D7: 5000 | F7: =E7*D7 -> 0
A8: MARVEL LA HISTORIA VISUAL | B8: 1980 A 1984 UN UNIVERSO EN EVOLUCIÓN | C8: 9780241388211 | D8: 5000 | F8: =E8*D8 -> 0
A9: MARVEL LA HISTORIA VISUAL | B9: 1985 A 1989 EMPIEZA UN NUEVO ORDEN | C9: 9780241388228 | D9: 5000 | F9: =E9*D9 -> 0
A10: MARVEL LA HISTORIA VISUAL | B10: 1990 A 1994 ARTISTAS ESTRELLA | C10: 9780241388235 | D10: 5000 | F10: =E10*D10 -> 0
A11: MARVEL LA HISTORIA VISUAL | B11: 1995 A 1999 NUEVOS COMIENZOS | C11: 9780241388259 | D11: 5000 | F11: =E11*D11 -> 0
A12: MARVEL LA HISTORIA VISUAL | B12: 2000 A 2004 CAMINO DE HOLLYWOOD | C12: 9780241388266 | D12: 5000 | F12: =E12*D12 -> 0
A13: MARVEL LA HISTORIA VISUAL | B13: 2005 A 2009 MARVEL VA A LA GUERRA | C13: 9780241388273 | D13: 5000 | F13: =E13*D13 -> 0
A14: MARVEL LA HISTORIA VISUAL | B14: 2010 a 2019 LA ERA DE LOS HÉROES | C14: 9780241388280 | D14: 5000 | F14: =E14*D14 -> 0
A15: STAR WARS - LA HISTORIA VISUAL
A16: STAR WARS LA HISTORIA VISUAL | B16: 1: LA VIDA ANTES DE STAR WARS Y UNA NUEVA ESPERANZA | C16: 9780241554463 | D16: 5000 | F16: =E16*D16 -> 0
A17: STAR WARS LA HISTORIA VISUAL | B17: 2: CONTINÚA LA TRILOGÍA ORIGINAL | C17: 9780241553817 | D17: 5000 | F17: =E17*D17 -> 0
A18: STAR WARS LA HISTORIA VISUAL | B18: 3: MÁS ALLÁ DEL CINE | C18: 9780241553824 | D18: 5000 | F18: =E18*D18 -> 0
A19: STAR WARS LA HISTORIA VISUAL | B19: 4: LA TRILOGÍA DE LAS PRECUELAS 1ERA PARTE | C19: 9780241553831 | D19: 5000 | F19: =E19*D19 -> 0
A20: STAR WARS LA HISTORIA VISUAL | B20: 5: LA TRILOGÍA DE LAS PRECUELAS SEGUNDA PARTE | C20: 9780241553848 | D20: 5000 | F20: =E20*D20 -> 0
A21: STAR WARS LA HISTORIA VISUAL | B21: 6: DE LAS GUERRAS DE LOS CLONES EN ADELANTE | C21: 9780241553855 | D21: 5000 | F21: =E21*D21 -> 0
A22: STAR WARS LA HISTORIA VISUAL | B22: 7: UNA NUEVA ERA Y EL DESPERTAR DE LA FUERZA | C22: 9780241553862 | D22: 5000 | F22: =E22*D22 -> 0
A23: STAR WARS LA HISTORIA VISUAL | B23: 8: CONTINÚA LA TRILOGÍA DE SECUELAS - EL FUTURO DE LA SAGA | C23: 9780241553879 | D23: 5000 | F23: =E23*D23 -> 0
A24: BATMAN - LA HISTORIA VISUAL
A25: BATMAN LA HISTORIA VISUAL | B25: EL CABALLERO OSCURO 1930-1940 | C25: 9780241419519 | D25: 5000 | F25: =E25*D25 -> 0
A26: BATMAN LA HISTORIA VISUAL | B26: UNA NUEVA DIMENSIÓN 1950 | C26: 9780241419526 | D26: 5000 | F26: =E26*D26 -> 0
A27: BATMAN LA HISTORIA VISUAL | B27: EL CRUZADO DE LA CAPA 1960 | C27: 9780241419540 | D27: 5000 | F27: =E27*D27 -> 0
A28: BATMAN LA HISTORIA VISUAL | B28: UN CABALLERO MAS OSCURO 1970 | C28: 9780241419557 | D28: 5000 | F28: =E28*D28 -> 0
A29: BATMAN LA HISTORIA VISUAL | B29: EL REGRESO DEL CABALLERO OSCURO 1980 | C29: 9780241419571 | D29: 5000 | F29: =E29*D29 -> 0
A30: BATMAN LA HISTORIA VISUAL | B30: LA SOMBRA DEL MURCIÉLAGO 1990 | C30: 9780241419588 | D30: 5000 | F30: =E30*D30 -> 0
A31: BATMAN LA HISTORIA VISUAL | B31: BATMAN Y ROBIN RENACIDOS 2000 | C31: 9780241419595 | D31: 5000 | F31: =E31*D31 -> 0
A32: BATMAN LA HISTORIA VISUAL | B32: UNA NUEVA LEYENDA 2010 | C32: 9780241419601 | D32: 5000 | F32: =E32*D32 -> 0
A33: ARTEMISA - ELIGE TU PROPIA AVENTURA
A34: R. A. Montgomery | B34: EL ESPACIO Y MAS ALLA-1 | C34: 9789876748544 | D34: 16900 | F34: =E34*D34 -> 0
A35: R. A. Montgomery | B35: VIAJE BAJO EL MAR-2 | C35: 9789876748513 | D35: 16900 | F35: =E35*D35 -> 0
A36: R. A. Montgomery | B36: REGRESO A LA ATLANTIDA-3 | C36: 9789876748520 | D36: 16900 | F36: =E36*D36 -> 0
A37: R. A. Montgomery | B37: EL ABOMINABLE HOMBRE DE LA NIEVE-4 | C37: 9789876748506 | D37: 16900 | F37: =E37*D37 -> 0
A38: Deborah Lerme Goodman | B38: LA MAGIA DEL UNICORNIO-5 | C38: 9789876748568 | D38: 16900 | F38: =E38*D38 -> 0
A39: R. A. Montgomery | B39: LA CASA DEL PELIGRO-6 | C39: 9789876748537 | D39: 16900 | F39: =E39*D39 -> 0
A40: R. A. Montgomery | B40: LA BRILLANTE DRA WOGAN-7 | C40: 9789876748575 | D40: 16900 | F40: =E40*D40 -> 0
...

Sheet Merchandising
A2: PRODUCTO | B2: ISBN | C2: Precio | D2: Cantidad | E2: Subotal
A3: BANDANA KONOHA NARUTO | B3: S/D | C3: 1250 | E3: =D3*C3 -> 0
A4: BANDANA TACHADA NARUTO | B4: S/D | C4: 1250 | E4: =D4*C4 -> 0
A5: BANDANA KONOHA AZUL NARUTO | B5: S/D | C5: 1250 | E5: =D5*C5 -> 0
A6: KUNAI NARUTO | B6: S/D | C6: 1100 | E6: =D6*C6 -> 0
A7: SHURIKEN NARUTO | B7: S/D | C7: 1100 | E7: =D7*C7 -> 0
A8: CUCHILLAS NARUTO | B8: S/D | C8: 1100 | E8: =D8*C8 -> 0
A9: LIBRETA DEATH NOTE | B9: S/D | C9: 6000 | E9: =D9*C9 -> 0
A10: VASOS DE PLÁSTICO ANIME (CONSULTA MODELOS) | B10: S/D | C10: 800 | E10: =D10*C10 -> 0
A11: ANTEOJOS MEME PIXEL | B11: S/D | C11: 3000 | E11: =D11*C11 -> 0 | F11: 15% DESCUENTO LLEVANDO 50 UNIDADES O MAS
A12: MOCHILA SAKURA DE CUERO SINTÉTICO | B12: S/D | C12: 28000 | E12: =D12*C12 -> 0 | F12: 15% DESCUENTO LLEVANDO 50 UNIDADES O MAS
A13: PACK ESFERAS DEL DRAGON 7 ESFERAS 4CM | B13: S/D | C13: 28000 | E13: =D13*C13 -> 0
A14: ESFERA DEL DRAGON 4 ESTRELLAS GRANDE 10CM | B14: S/D | C14: 25500 | E14: =D14*C14 -> 0 | F14: 15% DESCUENTO LLEVANDO 50 UNIDADES O MAS
A15: ESFERA DEL DRAGÓN 4 ESTRELLAS LLAVERO 4CM | B15: S/D | C15: 3000 | E15: =D15*C15 -> 0 | F15: 15% DESCUENTO LLEVANDO 50 UNIDADES O MAS
A16: CARTAS CLOW SAKURA EN CAJA DE CARTON | B16: S/D | C16: 13000 | E16: =D16*C16 -> 0
A17: CARTAS CLOW SAKURA ROSA EN CAJA DE CARTON | B17: S/D | C17: 13000 | E17: =D17*C17 -> 0
A18: CARTAS CLOW SAKURA CLEAR CARD ARC | B18: S/D | C18: 13000 | E18: =D18*C18 -> 0
A19: CORBATA HARRY POTTER GRYFFINDOR | B19: S/D | C19: 5000 | E19: =D19*C19 -> 0
A20: CORBATA HARRY POTTER SLYTHERIN | B20: S/D | C20: 5000 | E20: =D20*C20 -> 0
A21: CORBATA HARRY POTTER HUFFLEPUFF | B21: S/D | C21: 5000 | E21: =D21*C21 -> 0
A22: CORBATA HARRY POTTER RAVENCLAW | B22: S/D | C22: 5000 | E22: =D22*C22 -> 0
A23: MONEDERO SAPO NARUTO | B23: S/D | C23: 4000 | E23: =D23*C23 -> 0 | F23: 15% DESCUENTO LLEVANDO 50 UNIDADES O MAS
A24: COLGANTE GIRATIEMPOS HARRY POTTER | B24: S/D | C24: 3000 | E24: =D24*C24 -> 0 | F24: 15% DESCUENTO LLEVANDO 50 UNIDADES O MAS
A25: LENTES HARRY POTTER | B25: S/D | C25: 3000 | E25: =D25*C25 -> 0 | F25: 15% DESCUENTO LLEVANDO 50 UNIDADES O MAS
A26: CAJA MUSICAL MI VECINO TOTORO | B26: S/D | C26: 9500 | E26: =D26*C26 -> 0
A27: CAJA MUSICAL EL VIAJE DE CHIHIRO | B27: S/D | C27: 9500 | E27: =D27*C27 -> 0
A28: CAJA MUSICAL SAILOR MOON ROSA MODELO 2 | B28: S/D | C28: 9500 | E28: =D28*C28 -> 0
A29: CAJA MUSICAL HARRY POTTER ORDEN DEL FENIX | B29: S/D | C29: 9500 | E29: =D29*C29 -> 0
A30: CAJA MUSICAL HARRY POTTER 9 3/4 ROJA | B30: S/D | C30: 9500 | E30: =D30*C30 -> 0
A31: CAJA MUSICAL MICHAEL JACKSON | B31: S/D | C31: 9500 | E31: =D31*C31 -> 0
A32: CAJA MUSICAL ATTACK ON TITAN | B32: S/D | C32: 9500 | E32: =D32*C32 -> 0
A33: CAJA MUSICAL SAILOR MOON (MODELO EN NEGRO O ROSA) | B33: S/D | C33: 9500 | E33: =D33*C33 -> 0
A34: CAJA MUSICAL DEMON SLAYER | B34: S/D | C34: 9500 | E34: =D34*C34 -> 0
A35: CAJA MUSICAL JURASSIC PARK | B35: S/D | C35: 9500 | E35: =D35*C35 -> 0
A36: CAJA MUSICAL DRAGON BALL | B36: S/D | C36: 9500 | E36: =D36*C36 -> 0
A37: CAJA MUSICAL ZELDA | B37: S/D | C37: 9500 | E37: =D37*C37 -> 0
... A77: LAMPARA LED UNICORNIO SILICONA | B77: S/D | C77: 25000 | E77: =D77*C77 -> 0
A78: LAMPARA VELADOR MARIO SIGNO PREGUNTA | B78: 6986764008862 | C78: 16000 | E78: =D78*C78 -> 0
A79: LAMPARA VELADOR MARIO HONGO VERDE | B79: 5055964714215 | C79: 16000 | E79: =D79*C79 -> 0
A80: LAMPARA VELADOR MARIO HONGO ROJO | B80: 5055964714215 | C80: 16000 | E80: =D80*C80 -> 0
...
